Workbook

Sheet Summary
B2: Bioinformatics Competency Assessment Record v0.1
B4: Name | C4: name
B5: Position | C5: e.g. Senior Bioinformatician
B7: Summary
B9: Competency Area | D9: Competency | E9: Level | F9: Date assessed | G9: Status warning
B10: 1. Biology and computer science knowledge | D10: ='Competency Area 1'!B6 -> 1.1 Biology principles | E10: ='Competency Area 1'!C19 -> Competent | F10: ='Competency Area 1'!E21 -> 44387 | G10: =IF(OR(F10=0,F10=""),"",IF(F10<EDATE(TODAY(),-B$37),"Competency has expired", IF(F10<EDATE(TODAY(),-B$37)+B$40,"Competency expires within "&B$40&" days",""))) -> Competency has expired
D11: ='Competency Area 1'!B24 -> 1.2 Computer science principles | E11: ='Competency Area 1'!C37 -> 0 | F11: ='Competency Area 1'!E39 -> 0 | G11: =IF(OR(F11=0,F11=""),"",IF(F11<EDATE(TODAY(),-B$37),"Competency has expired", IF(F11<EDATE(TODAY(),-B$37)+B$40,"Competency expires within "&B$40&" days","")))
B12: 2. Statistical methods knowledge | D12: ='Competency Area 2'!B6 -> 2.1 Statistical analysis | E12: ='Competency Area 2'!C19 -> 0 | F12: ='Competency Area 2'!E21 -> 0 | G12: =IF(OR(F12=0,F12=""),"",IF(F12<EDATE(TODAY(),-B$37),"Competency has expired", IF(F12<EDATE(TODAY(),-B$37)+B$40,"Competency expires within "&B$40&" days","")))
B13: 3. Biological data analysis | D13: ='Competency Area 3'!B6 -> 3.1 Analysis | E13: ='Competency Area 3'!C19 -> 0 | F13: ='Competency Area 3'!E21 -> 0 | G13: =IF(OR(F13=0,F13=""),"",IF(F13<EDATE(TODAY(),-B$37),"Competency has expired", IF(F13<EDATE(TODAY(),-B$37)+B$40,"Competency expires within "&B$40&" days","")))
D14: ='Competency Area 3'!B24 -> 3.2 Interpretation | E14: ='Competency Area 3'!C37 -> 0 | F14: ='Competency Area 3'!E39 -> 0 | G14: =IF(OR(F14=0,F14=""),"",IF(F14<EDATE(TODAY(),-B$37),"Competency has expired", IF(F14<EDATE(TODAY(),-B$37)+B$40,"Competency expires within "&B$40&" days","")))
D15: ='Competency Area 3'!B42 -> 3.3 Visualization | E15: ='Competency Area 3'!C55 -> 0 | F15: ='Competency Area 3'!E57 -> 0 | G15: =IF(OR(F15=0,F15=""),"",IF(F15<EDATE(TODAY(),-B$37),"Competency has expired", IF(F15<EDATE(TODAY(),-B$37)+B$40,"Competency expires within "&B$40&" days","")))
D16: ='Competency Area 3'!B60 -> 3.4 Communication | E16: ='Competency Area 3'!C73 -> 0 | F16: ='Competency Area 3'!E75 -> 0 | G16: =IF(OR(F16=0,F16=""),"",IF(F16<EDATE(TODAY(),-B$37),"Competency has expired", IF(F16<EDATE(TODAY(),-B$37)+B$40,"Competency expires within "&B$40&" days","")))
B17: 4. Biological data management | D17: ='Competency Area 4'!B6 -> 4.1 Data structures | E17: ='Competency Area 4'!C19 -> 0 | F17: ='Competency Area 4'!E21 -> 0 | G17: =IF(OR(F17=0,F17=""),"",IF(F17<EDATE(TODAY(),-B$37),"Competency has expired", IF(F17<EDATE(TODAY(),-B$37)+B$40,"Competency expires within "&B$40&" days","")))
D18: ='Competency Area 4'!B24 -> 4.2 Data management | E18: ='Competency Area 4'!C37 -> 0 | F18: ='Competency Area 4'!E39 -> 0 | G18: =IF(OR(F18=0,F18=""),"",IF(F18<EDATE(TODAY(),-B$37),"Competency has expired", IF(F18<EDATE(TODAY(),-B$37)+B$40,"Competency expires within "&B$40&" days","")))
D19: ='Competency Area 4'!B42 -> 4.3 Storage and retrieval | E19: ='Competency Area 4'!C55 -> 0 | F19: ='Competency Area 4'!E57 -> 0 | G19: =IF(OR(F19=0,F19=""),"",IF(F19<EDATE(TODAY(),-B$37),"Competency has expired", IF(F19<EDATE(TODAY(),-B$37)+B$40,"Competency expires within "&B$40&" days","")))
B20: 5. Domain specific expertise | D20: ='Competency Area 5'!B6 -> 5.1 Genomic epidemiology | E20: ='Competency Area 5'!C19 -> Competent | F20: ='Competency Area 5'!E21 -> 45155 | G20: =IF(OR(F20=0,F20=""),"",IF(F20<EDATE(TODAY(),-B$37),"Competency has expired", IF(F20<EDATE(TODAY(),-B$37)+B$40,"Competency expires within "&B$40&" days",""))) -> Competency expires within 90 days
D21: ='Competency Area 5'!B24 -> 5.2 Population genomics | E21: ='Competency Area 5'!C37 -> 0 | F21: ='Competency Area 5'!E39 -> 0 | G21: =IF(OR(F21=0,F21=""),"",IF(F21<EDATE(TODAY(),-B$37),"Competency has expired", IF(F21<EDATE(TODAY(),-B$37)+B$40,"Competency expires within "&B$40&" days","")))
D22: ='Competency Area 5'!B42 -> 5.3 Pathogen genomics | E22: ='Competency Area 5'!C55 -> 0 | F22: ='Competency Area 5'!E57 -> 0 | G22: =IF(OR(F22=0,F22=""),"",IF(F22<EDATE(TODAY(),-B$37),"Competency has expired", IF(F22<EDATE(TODAY(),-B$37)+B$40,"Competency expires within "&B$40&" days","")))
B23: 6. System administration | D23: ='Competency Area 6'!B6 -> 6.1 Compute allocation | E23: ='Competency Area 6'!C19 -> 0 | F23: ='Competency Area 6'!E21 -> 0 | G23: =IF(OR(F23=0,F23=""),"",IF(F23<EDATE(TODAY(),-B$37),"Competency has expired", IF(F23<EDATE(TODAY(),-B$37)+B$40,"Competency expires within "&B$40&" days","")))
D24: ='Competency Area 6'!B24 -> 6.2 Software and environments | E24: ='Competency Area 6'!C37 -> 0 | F24: ='Competency Area 6'!E39 -> 0 | G24: =IF(OR(F24=0,F24=""),"",IF(F24<EDATE(TODAY(),-B$37),"Competency has expired", IF(F24<EDATE(TODAY(),-B$37)+B$40,"Competency expires within "&B$40&" days","")))
D25: ='Competency Area 6'!B42 -> 6.3 Storage and lifecycle | E25: ='Competency Area 6'!C55 -> 0 | F25: ='Competency Area 6'!E57 -> 0 | G25: =IF(OR(F25=0,F25=""),"",IF(F25<EDATE(TODAY(),-B$37),"Competency has expired", IF(F25<EDATE(TODAY(),-B$37)+B$40,"Competency expires within "&B$40&" days","")))
D26: ='Competency Area 6'!B60 -> 6.4 System monitoring | E26: ='Competency Area 6'!C73 -> 0 | F26: ='Competency Area 6'!E75 -> 0 | G26: =IF(OR(F26=0,F26=""),"",IF(F26<EDATE(TODAY(),-B$37),"Competency has expired", IF(F26<EDATE(TODAY(),-B$37)+B$40,"Competency expires within "&B$40&" days","")))
D27: ='Competency Area 6'!B78 -> 6.5 Security and access | E27: ='Competency Area 6'!C91 -> 0 | F27: ='Competency Area 6'!E93 -> 0 | G27: =IF(OR(F27=0,F27=""),"",IF(F27<EDATE(TODAY(),-B$37),"Competency has expired", IF(F27<EDATE(TODAY(),-B$37)+B$40,"Competency expires within "&B$40&" days","")))
B28: 7. Workflow engineering and software development | D28: ='Competency Area 7'!B6 -> 7.1 Pipeline orchestration | E28: ='Competency Area 7'!C19 -> 0 | F28: ='Competency Area 7'!E21 -> 0 | G28: =IF(OR(F28=0,F28=""),"",IF(F28<EDATE(TODAY(),-B$37),"Competency has expired", IF(F28<EDATE(TODAY(),-B$37)+B$40,"Competency expires within "&B$40&" days","")))
D29: ='Competency Area 7'!B24 -> 7.2 Containers and reproducibility | E29: ='Competency Area 7'!C37 -> 0 | F29: ='Competency Area 7'!E39 -> 0 | G29: =IF(OR(F29=0,F29=""),"",IF(F29<EDATE(TODAY(),-B$37),"Competency has expired", IF(F29<EDATE(TODAY(),-B$37)+B$40,"Competency expires within "&B$40&" days","")))
D30: ='Competency Area 7'!B42 -> 7.3 Bioinformatics software | E30: ='Competency Area 7'!C55 -> 0 | F30: ='Competency Area 7'!E57 -> 0 | G30: =IF(OR(F30=0,F30=""),"",IF(F30<EDATE(TODAY(),-B$37),"Competency has expired", IF(F30<EDATE(TODAY(),-B$37)+B$40,"Competency expires within "&B$40&" days","")))
D31: ='Competency Area 7'!B60 -> 7.4 Version control and collaboration | E31: ='Competency Area 7'!C73 -> Proficient | F31: ='Competency Area 7'!E75 -> 45670 | G31: =IF(OR(F31=0,F31=""),"",IF(F31<EDATE(TODAY(),-B$37),"Competency has expired", IF(F31<EDATE(TODAY(),-B$37)+B$40,"Competency expires within "&B$40&" days","")))
B32: 8. Quality management | D32: ='Competency Area 8'!B6 -> 8.1 Document control | E32: ='Competency Area 8'!C19 -> 0 | F32: ='Competency Area 8'!E21 -> 0 | G32: =IF(OR(F32=0,F32=""),"",IF(F32<EDATE(TODAY(),-B$37),"Competency has expired", IF(F32<EDATE(TODAY(),-B$37)+B$40,"Competency expires within "&B$40&" days","")))
D33: ='Competency Area 8'!B24 -> 8.2 Validation | E33: ='Competency Area 8'!C37 -> 0 | F33: ='Competency Area 8'!E39 -> 0 | G33: =IF(OR(F33=0,F33=""),"",IF(F33<EDATE(TODAY(),-B$37),"Competency has expired", IF(F33<EDATE(TODAY(),-B$37)+B$40,"Competency expires within "&B$40&" days","")))
D34: ='Competency Area 8'!B42 -> 8.3 Auditing | E34: ='Competency Area 8'!C55 -> 0 | F34: ='Competency Area 8'!E57 -> 0 | G34: =IF(OR(F34=0,F34=""),"",IF(F34<EDATE(TODAY(),-B$37),"Competency has expired", IF(F34<EDATE(TODAY(),-B$37)+B$40,"Competency expires within "&B$40&" days","")))
B36: Validity timeframe
B37: 36 | C37: months
B39: Warning timeframe
B40: 90 | C40: days
B43: Guidance notes
B44: This competency assessment record has been produced by the advISO project for recording and assessing the competency of bioinformatics staff against the advISO Bioinformatics Competency Framework.
B46: How to use this workbook
B47: 1. Each competency area (1–8) has its own tab, containing the individual competencies within that area (e.g. 1.1, 1.2).
B48: 2. For each competency, the staff member reviews the level descriptors (Beginner, Competent, Proficient, Expert) and enters supporting evidence in the "Evidence" box, along with the level they consider themselves to have achieved ("Level proposed").
B49: 3. An assessor (a senior team member) reviews the evidence, records their comments in the "Assessor comments" box, confirms the agreed level in "Level agreed", and enters their name and the date approved.
...

Sheet Competency Area 1
B2: Competency Area 1: Biological and Computer Science Knowledge
B4: Objective: Develops new understandings of computer science domains to apply to biological problems
B6: 1.1 Biology principles
B8: Level | C8: Description
B9: Beginner | C9: Identifies potential biological problems to be addressed by computer science techniques
B10: Competent | C10: Determines biological problems to be addressed by computer science techniques
B11: Proficient | C11: Evaluates the effectiveness of the selected computer science technique(s) in addressing biological problems
B12: Expert | C12: Selects biological problems to be addressed by computer science techniques
B14: Evidence
B15: Level proposed: | C15: Competent
B18: Assessor comments
B19: Level agreed: | C19: Competent
B21: Assessed by: | D21: Date appoved: | E21: 44387
B24: 1.2 Computer science principles
B26: Level | C26: Description
B27: Beginner | C27: Identifies computer science domains to apply to biological problems
B28: Competent | C28: Applies computer science domains to biological problems
B29: Proficient | C29: Evaluates computer science domains to apply to biological problems
B30: Expert | C30: Evaluates computer science domains to apply to biological problems
B32: Evidence
B33: Level proposed:
B36: Assessor comments
B37: Level agreed:
B39: Assessed by: | D39: Date appoved:

Sheet Competency Area 2
B2: Competency Area 2: Statistical Methods Knowledge
B4: Objective: Demonstrates the ability to apply knowledge of statistical methods for analysis of biological data
B6: 2.1 Statistical analysis
B8: Level | C8: Description
B9: Beginner | C9: Prepares data for processing
B10: Competent | C10: Uses simple statistical analysis to analyse trends and patterns and to draw conclusions related to the biological data
B11: Proficient | C11: Compares findings to any related data sets
B12: Expert | C12: Oversees selection of advanced statistical methods applicable to specific bioinformatics analyses
B14: Evidence
B15: Level proposed:
B18: Assessor comments
B19: Level agreed:
B21: Assessed by: | D21: Date appoved:

Sheet Competency Area 3
B2: Competency Area 3: Biological Data Analysis
B4: Objective: Demonstrates the ability analyse microbiological data, principally using genome sequence data
B6: 3.1 Analysis
B8: Level | C8: Description
B9: Beginner | C9: Selects which existing tools and algorithms to use for any given analysis
B10: Competent | C10: Determines options and parameters of tools to meet specified needs of a given data analysis
B11: Proficient | C11: Implements new software tools to address unmet needs or improve current processes
B12: Expert | C12: Creates stand-alone analysis tools/pipelines
B14: Evidence
B15: Level proposed:
B18: Assessor comments
B19: Level agreed:
B21: Assessed by: | D21: Date appoved:
B24: 3.2 Interpretation
B26: Level | C26: Description
B27: Beginner | C27: Identifies data pertinent to the analysis problem
B28: Competent | C28: Formulates results of analyses, including information in the form of graphs, charts, and tables
B29: Proficient | C29: Interprets results within the context of the analysis problem
B30: Expert | C30: Generates hypotheses to predict future implications based on the evaluation of data analyses
B32: Evidence
B33: Level proposed:
B36: Assessor comments
B37: Level agreed:
B39: Assessed by: | D39: Date appoved:
B42: 3.3 Visualization
B44: Level | C44: Description
B45: Beginner | C45: Uses data visualization and representation tools to present results of data analyses
B46: Competent | C46: Selects visualization and representation tools for specified bioinformatics problems
B47: Proficient | C47: Evaluates representation and visualization tools for summarizing data analyses
B48: Expert | C48: Modifies existing visualization and representation tools to provide insight into bioinformatics analyses
B50: Evidence
B51: Level proposed:
B54: Assessor comments
B55: Level agreed:
B57: Assessed by: | D57: Date appoved:
B60: 3.4 Communication
B62: Level | C62: Description
B63: Beginner | C63: Discusses bioinformatics with other scientists within their institution
B64: Competent | C64: Initiates bioinformatics collaborations with colleague
B65: Proficient | C65: Facilitates knowledge-sharing with stakeholders
...

Sheet Competency Area 4
B2: Competency Area 4: Biological Data Management
B4: Objective: Demonstrates the ability to perform data management, storage, and retrieval
B6: 4.1 Data structures
B8: Level | C8: Description
B9: Beginner | C9: Demonstrates basic knowledge of data structures
B10: Competent | C10: Applies knowledge of data structures to relevant problems
B11: Proficient | C11: Manipulates data structures to address biological problems
B12: Expert | C12: Develops new data structures
B14: Evidence
B15: Level proposed:
B18: Assessor comments
B19: Level agreed:
B21: Assessed by: | D21: Date appoved:
B24: 4.2 Data management
B26: Level | C26: Description
B27: Beginner | C27: Describes data management techniques
B28: Competent | C28: Applies knowledge of data management techniques to relevant problems
B29: Proficient | C29: Evaluates data management techniques
B30: Expert | C30: Develops new data management techniques
B32: Evidence
B33: Level proposed:
B36: Assessor comments
B37: Level agreed:
B39: Assessed by: | D39: Date appoved:
B42: 4.3 Storage and retrieval
B44: Level | C44: Description
B45: Beginner | C45: Describes data storage and retrieval techniques
B46: Competent | C46: Applies knowledge of data storage and retrieval techniques
B47: Proficient | C47: Evaluates data storage and retrieval techniques
B48: Expert | C48: Develops new data storage and retrieval techniques
B50: Evidence
B51: Level proposed:
B54: Assessor comments
B55: Level agreed:
B57: Assessed by: | D57: Date appoved:

Sheet Competency Area 5
B2: Competency Area 5: Domain-Specific Expertise
B4: Objective: Demonstrates domain specific expertise to support activities undertaken in unit and provide informed advice
B6: 5.1 Genomic epidemiology
B8: Level | C8: Description
B9: Beginner | C9: Is able to perform basic interpretation of phylogenetic trees
B10: Competent | C10: Understands different methods for inferring transmissions (e.g. SNP addressing) and can use this to predict transmission
B11: Proficient | C11: Understands confounders (such as recombination) that can affect transmission inference and how this can be mitigated
B12: Expert | C12: Is able to undertake and develop advanced, model-based approaches to infer transmission events
B14: Evidence
B15: Level proposed:
B18: Assessor comments
B19: Level agreed: | C19: Competent
B21: Assessed by: | D21: Date appoved: | E21: 45155
B24: 5.2 Population genomics
B26: Level | C26: Description
B27: Beginner | C27: Understands the application of basic clustering approaches to subdivide populations
B28: Competent | C28: Is able to use clustering approaches to subdivide populations and detect recombination
B29: Proficient | C29: Is able to integrate clustering approaches into other analyses to understand the population structure of pathogens
B30: Expert | C30: Is able to develop new clustering algorithms to subdivide populations
B32: Evidence
B33: Level proposed:
B36: Assessor comments
B37: Level agreed:
B39: Assessed by: | D39: Date appoved:
B42: 5.3 Pathogen genomics
B44: Level | C44: Description
B45: Beginner | C45: Is able to perform pairwise comparative genomics investigations
B46: Competent | C46: Is able to work with multiple genomes to characterise genomic differences
B47: Proficient | C47: Is able to use pathogen genomics to characterise samples with respect to databases of organisms and genes
B48: Expert | C48: Contributes novel findings about pathogens using genomics. Is able to develop and apply new approaches/ways of analysing pathogen genomic data
B50: Evidence
B51: Level proposed:
B54: Assessor comments
B55: Level agreed:
B57: Assessed by: | D57: Date appoved:

Sheet Competency Area 6
B2: Competency Area 6: System administration
B4: Objective: Carries out the infrastructure-focused responsibilities necessary to maintain, secure, and optimise the computational environment used for bioinformatics
B6: 6.1 Compute allocation
B8: Level | C8: Description
B9: Beginner | C9: Describe available computing resources and capacity
B10: Competent | C10: Allocates computing resources
B11: Proficient | C11: Manages allocation of multiple computing resources
B12: Expert | C12: Develops new methods for allocation of computing resources
B14: Evidence
B15: Level proposed:
B18: Assessor comments
B19: Level agreed:
B21: Assessed by: | D21: Date appoved:
B24: 6.2 Software and environments
B26: Level | C26: Description
B27: Beginner | C27: Installs software using established procedures
B28: Competent | C28: Maintains software stacks and manages environments (e.g. conda)
B29: Proficient | C29: Optimises environments, resolves dependency issues, and ensures reproducibility
B30: Expert | C30: Designs organisation-wide environment strategies and standardised software stacks
B32: Evidence
B33: Level proposed:
B36: Assessor comments
B37: Level agreed:
B39: Assessed by: | D39: Date appoved:
B42: 6.3 Storage and lifecycle
B44: Level | C44: Description
B45: Beginner | C45: Describes storage systems and follows data-organisation procedures
B46: Competent | C46: Manages storage allocation and applies retention policies
B47: Proficient | C47: Oversees data lifecycle processes including archival, backup, and retrieval
B48: Expert | C48: Designs large-scale storage architectures and long-term data-lifecycle strategies
B50: Evidence
B51: Level proposed:
B54: Assessor comments
B55: Level agreed:
B57: Assessed by: | D57: Date appoved:
B60: 6.4 System monitoring
B62: Level | C62: Description
B63: Beginner | C63: Uses basic monitoring tools to observe system status
B64: Competent | C64: Identifies simple performance issues and reports them appropriately
B65: Proficient | C65: Diagnoses and resolves performance issues across compute and storage systems
...

Sheet Competency Area 7
B2: Competency Area 7: Workflow engineering and software development
B4: Objective: Demonstrates the ability to develop, maintain, and optimise bioinformatics pipelines, workflows, and supporting software
B6: 7.1 Pipeline orchestration
B8: Level | C8: Description
B9: Beginner | C9: Runs existing workflows using standard parameters
B10: Competent | C10: Modifies workflow parameters and resolves routine failures
B11: Proficient | C11: Designs and maintains workflows using engines such as Nextflow
B12: Expert | C12: Develops organisation-wide workflow strategies and optimises distributed execution
B14: Evidence
B15: Level proposed:
B18: Assessor comments
B19: Level agreed:
B21: Assessed by: | D21: Date appoved:
B24: 7.2 Containers and reproducibility
B26: Level | C26: Description
B27: Beginner | C27: Uses existing containers (Docker/Singularity)
B28: Competent | C28: Builds simple containers for routine analyses
B29: Proficient | C29: Designs reproducible containerised environments for pipelines
B30: Expert | C30: Develops container strategies and maintains internal registries
B32: Evidence
B33: Level proposed:
B36: Assessor comments
B37: Level agreed:
B39: Assessed by: | D39: Date appoved:
B42: 7.3 Bioinformatics software
B44: Level | C44: Description
B45: Beginner | C45: Writes simple scripts following templates
B46: Competent | C46: Develops small tools and contributes to shared codebases
B47: Proficient | C47: Designs robust, maintainable tools and follows best practices (testing, versioning)
B48: Expert | C48: Leads development of new tools, frameworks, or libraries
B50: Evidence
B51: Level proposed:
B54: Assessor comments
B55: Level agreed:
B57: Assessed by: | D57: Date appoved:
B60: 7.4 Version control and collaboration
B62: Level | C62: Description
B63: Beginner | C63: Uses Git to track changes
B64: Competent | C64: Works with branches, pull requests, and reviews
B65: Proficient | C65: Manages repositories and enforces coding standards
...

Sheet Competency Area 8
B2: Competency Area 8: Quality Management
B4: Objective: Demonstrates expertise to support quality management activities undertaken in unit and provide informed advice
B6: 8.1 Document control
B8: Level | C8: Description
B9: Beginner | C9: Understand the reason and need for document control processes
B10: Competent | C10: Can draft and carry out reviews of documentation and provide viable feedback
B11: Proficient | C11: Can utilise and navigate controlled documents within the QMS with sufficient skill and knowledge, and can add tasks for users to complete within the QMS
B12: Expert | C12: Can review, authorise, and publish new documentation within the QMS
B14: Evidence
B15: Level proposed:
B18: Assessor comments
B19: Level agreed:
B21: Assessed by: | D21: Date appoved:
B24: 8.2 Validation
B26: Level | C26: Description
B27: Beginner | C27: Understands the purpose of validation and follows established procedures under supervision
B28: Competent | C28: Performs validation tasks independently, applies protocols correctly, and documents outcomes accurately
B29: Proficient | C29: Designs validation plans, evaluates results, and advises on appropriate validation methods
B30: Expert | C30: Leads validation activities, defines standards and acceptance criteria, and develops organisation-wide validation approaches
B32: Evidence
B33: Level proposed:
B36: Assessor comments
B37: Level agreed:
B39: Assessed by: | D39: Date appoved:
B42: 8.3 Auditing
B44: Level | C44: Description
B45: Beginner | C45: Understands the purpose of audits and follows established audit procedures under supervision
B46: Competent | C46: Carries out audit tasks independently, gathers evidence, and documents findings accurately
B47: Proficient | C47: Plans audits, evaluates compliance, identifies non-conformities, and advises on corrective actions
B48: Expert | C48: Leads audit activities, defines audit strategies, and oversees organisation-wide audit processes
B50: Evidence
B51: Level proposed:
B54: Assessor comments
B55: Level agreed:
B57: Assessed by: | D57: Date appoved:
